DEBUG 2024-10-28 16:01:47,322 base Exception while resolving variable 'name' in template 'unknown'.
Traceback (most recent call last):
  File "/usr/local/lib/python3.12/site-packages/django/core/handlers/exception.py", line 55, in inner
    response = get_response(request)
               ^^^^^^^^^^^^^^^^^^^^^
  File "/usr/local/lib/python3.12/site-packages/django/core/handlers/base.py", line 181, in _get_response
    callback, callback_args, callback_kwargs = self.resolve_request(request)
                                               ^^^^^^^^^^^^^^^^^^^^^^^^^^^^^
  File "/usr/local/lib/python3.12/site-packages/django/core/handlers/base.py", line 313, in resolve_request
    resolver_match = resolver.resolve(request.path_info)
                     ^^^^^^^^^^^^^^^^^^^^^^^^^^^^^^^^^^^
  File "/usr/local/lib/python3.12/site-packages/django/urls/resolvers.py", line 705, in resolve
    raise Resolver404({"tried": tried, "path": new_path})
django.urls.exceptions.Resolver404: {'tried': [[<URLResolver <URLPattern list> (admin:admin) 'admin/'>], [<URLPattern '' [name='home']>], [<URLResolver <module 'users.urls' from '/app/users/urls.py'> (None:None) ''>, <URLPattern 'register/' [name='register']>], [<URLResolver <module 'users.urls' from '/app/users/urls.py'> (None:None) ''>, <URLPattern 'login/' [name='login']>], [<URLResolver <module 'users.urls' from '/app/users/urls.py'> (None:None) ''>, <URLPattern 'oauth2/login/' [name='oauth2_login']>], [<URLResolver <module 'users.urls' from '/app/users/urls.py'> (None:None) ''>, <URLPattern 'oauth2/callback/' [name='oauth2_callback']>]], 'path': 'admin'}

During handling of the above exception, another exception occurred:

Traceback (most recent call last):
  File "/usr/local/lib/python3.12/site-packages/django/template/base.py", line 883, in _resolve_lookup
    current = current[bit]
              ~~~~~~~^^^^^
TypeError: 'URLResolver' object is not subscriptable

During handling of the above exception, another exception occurred:

Traceback (most recent call last):
  File "/usr/local/lib/python3.12/site-packages/django/template/base.py", line 893, in _resolve_lookup
    current = getattr(current, bit)
              ^^^^^^^^^^^^^^^^^^^^^
AttributeError: 'URLResolver' object has no attribute 'name'

During handling of the above exception, another exception occurred:

Traceback (most recent call last):
  File "/usr/local/lib/python3.12/site-packages/django/template/base.py", line 899, in _resolve_lookup
    current = current[int(bit)]
                      ^^^^^^^^
ValueError: invalid literal for int() with base 10: 'name'

During handling of the above exception, another exception occurred:

Traceback (most recent call last):
  File "/usr/local/lib/python3.12/site-packages/django/template/base.py", line 906, in _resolve_lookup
    raise VariableDoesNotExist(
django.template.base.VariableDoesNotExist: Failed lookup for key [name] in <URLResolver <URLPattern list> (admin:admin) 'admin/'>
DEBUG 2024-10-28 16:01:53,288 utils (0.003) SELECT "users_user"."id", "users_user"."password", "users_user"."last_login", "users_user"."is_superuser", "users_user"."username", "users_user"."first_name", "users_user"."last_name", "users_user"."email", "users_user"."is_staff", "users_user"."is_active", "users_user"."date_joined" FROM "users_user" WHERE "users_user"."username" = 'admin' LIMIT 21; args=('admin',); alias=default
